<?xml version="1.0" encoding="UTF-8"?>
<testsuites name="jest tests" tests="7" failures="7" errors="0" time="4.004">
  <testsuite name="E2E: Auth" errors="0" failures="7" skipped="0" timestamp="2025-06-19T13:56:11" time="3.74" tests="7">
    <testcase classname="E2E: Auth" name="should register a user" time="0.331">
      <failure>AggregateError: 
    at Function.Object.&lt;anonymous&gt;.AxiosError.from (/Users/daniellovazzano/Documents/Projects/pet-api-firebase/backend/node_modules/axios/lib/core/AxiosError.js:92:14)
    at RedirectableRequest.handleRequestError (/Users/daniellovazzano/Documents/Projects/pet-api-firebase/backend/node_modules/axios/lib/adapters/http.js:620:25)
    at RedirectableRequest.emit (node:events:507:28)
    at ClientRequest.eventHandlers.&lt;computed&gt; (/Users/daniellovazzano/Documents/Projects/pet-api-firebase/backend/node_modules/follow-redirects/index.js:49:24)
    at ClientRequest.emit (node:events:507:28)
    at emitErrorEvent (node:_http_client:104:11)
    at Socket.socketErrorListener (node:_http_client:518:5)
    at Socket.emit (node:events:507:28)
    at emitErrorNT (node:internal/streams/destroy:170:8)
    at emitErrorCloseNT (node:internal/streams/destroy:129:3)
    at processTicksAndRejections (node:internal/process/task_queues:90:21)
    at Axios.request (/Users/daniellovazzano/Documents/Projects/pet-api-firebase/backend/node_modules/axios/lib/core/Axios.js:45:41)
    at processTicksAndRejections (node:internal/process/task_queues:105:5)
    at Proxy.requestWrapper.&lt;computed&gt; (/Users/daniellovazzano/Documents/Projects/pet-api-firebase/backend/tests/e2e/helpers/request.js:69:19)
    at Object.&lt;anonymous&gt; (/Users/daniellovazzano/Documents/Projects/pet-api-firebase/backend/tests/e2e/auth/auth.e2e.js:49:25)</failure>
    </testcase>
    <testcase classname="E2E: Auth" name="should login user" time="0.068">
      <failure>AggregateError: 
    at Function.Object.&lt;anonymous&gt;.AxiosError.from (/Users/daniellovazzano/Documents/Projects/pet-api-firebase/backend/node_modules/axios/lib/core/AxiosError.js:92:14)
    at RedirectableRequest.handleRequestError (/Users/daniellovazzano/Documents/Projects/pet-api-firebase/backend/node_modules/axios/lib/adapters/http.js:620:25)
    at RedirectableRequest.emit (node:events:507:28)
    at ClientRequest.eventHandlers.&lt;computed&gt; (/Users/daniellovazzano/Documents/Projects/pet-api-firebase/backend/node_modules/follow-redirects/index.js:49:24)
    at ClientRequest.emit (node:events:507:28)
    at emitErrorEvent (node:_http_client:104:11)
    at Socket.socketErrorListener (node:_http_client:518:5)
    at Socket.emit (node:events:507:28)
    at emitErrorNT (node:internal/streams/destroy:170:8)
    at emitErrorCloseNT (node:internal/streams/destroy:129:3)
    at processTicksAndRejections (node:internal/process/task_queues:90:21)
    at Axios.request (/Users/daniellovazzano/Documents/Projects/pet-api-firebase/backend/node_modules/axios/lib/core/Axios.js:45:41)
    at processTicksAndRejections (node:internal/process/task_queues:105:5)
    at Proxy.requestWrapper.&lt;computed&gt; (/Users/daniellovazzano/Documents/Projects/pet-api-firebase/backend/tests/e2e/helpers/request.js:69:19)
    at Object.&lt;anonymous&gt; (/Users/daniellovazzano/Documents/Projects/pet-api-firebase/backend/tests/e2e/auth/auth.e2e.js:64:22)</failure>
    </testcase>
    <testcase classname="E2E: Auth" name="should deny login with wrong credentials" time="0.037">
      <failure>Error: expect(received).toBe(expected) // Object.is equality

Expected: 400
Received: undefined
    at Object.toBe (/Users/daniellovazzano/Documents/Projects/pet-api-firebase/backend/tests/e2e/auth/auth.e2e.js:86:36)
    at processTicksAndRejections (node:internal/process/task_queues:105:5)</failure>
    </testcase>
    <testcase classname="E2E: Auth" name="should access profile with token" time="0.023">
      <failure>AggregateError: 
    at Function.Object.&lt;anonymous&gt;.AxiosError.from (/Users/daniellovazzano/Documents/Projects/pet-api-firebase/backend/node_modules/axios/lib/core/AxiosError.js:92:14)
    at RedirectableRequest.handleRequestError (/Users/daniellovazzano/Documents/Projects/pet-api-firebase/backend/node_modules/axios/lib/adapters/http.js:620:25)
    at RedirectableRequest.emit (node:events:507:28)
    at ClientRequest.eventHandlers.&lt;computed&gt; (/Users/daniellovazzano/Documents/Projects/pet-api-firebase/backend/node_modules/follow-redirects/index.js:49:24)
    at ClientRequest.emit (node:events:507:28)
    at emitErrorEvent (node:_http_client:104:11)
    at Socket.socketErrorListener (node:_http_client:518:5)
    at Socket.emit (node:events:507:28)
    at emitErrorNT (node:internal/streams/destroy:170:8)
    at emitErrorCloseNT (node:internal/streams/destroy:129:3)
    at processTicksAndRejections (node:internal/process/task_queues:90:21)
    at Axios.request (/Users/daniellovazzano/Documents/Projects/pet-api-firebase/backend/node_modules/axios/lib/core/Axios.js:45:41)
    at processTicksAndRejections (node:internal/process/task_queues:105:5)
    at Proxy.requestWrapper.&lt;computed&gt; (/Users/daniellovazzano/Documents/Projects/pet-api-firebase/backend/tests/e2e/helpers/request.js:69:19)
    at Object.&lt;anonymous&gt; (/Users/daniellovazzano/Documents/Projects/pet-api-firebase/backend/tests/e2e/auth/auth.e2e.js:91:24)</failure>
    </testcase>
    <testcase classname="E2E: Auth" name="should deny access to profile without token" time="0.035">
      <failure>Error: expect(received).toBe(expected) // Object.is equality

Expected: 401
Received: undefined
    at Object.toBe (/Users/daniellovazzano/Documents/Projects/pet-api-firebase/backend/tests/e2e/auth/auth.e2e.js:108:36)
    at processTicksAndRejections (node:internal/process/task_queues:105:5)</failure>
    </testcase>
    <testcase classname="E2E: Auth" name="should login as superadmin" time="0.028">
      <failure>AggregateError: 
    at Function.Object.&lt;anonymous&gt;.AxiosError.from (/Users/daniellovazzano/Documents/Projects/pet-api-firebase/backend/node_modules/axios/lib/core/AxiosError.js:92:14)
    at RedirectableRequest.handleRequestError (/Users/daniellovazzano/Documents/Projects/pet-api-firebase/backend/node_modules/axios/lib/adapters/http.js:620:25)
    at RedirectableRequest.emit (node:events:507:28)
    at ClientRequest.eventHandlers.&lt;computed&gt; (/Users/daniellovazzano/Documents/Projects/pet-api-firebase/backend/node_modules/follow-redirects/index.js:49:24)
    at ClientRequest.emit (node:events:507:28)
    at emitErrorEvent (node:_http_client:104:11)
    at Socket.socketErrorListener (node:_http_client:518:5)
    at Socket.emit (node:events:507:28)
    at emitErrorNT (node:internal/streams/destroy:170:8)
    at emitErrorCloseNT (node:internal/streams/destroy:129:3)
    at processTicksAndRejections (node:internal/process/task_queues:90:21)
    at Axios.request (/Users/daniellovazzano/Documents/Projects/pet-api-firebase/backend/node_modules/axios/lib/core/Axios.js:45:41)
    at processTicksAndRejections (node:internal/process/task_queues:105:5)
    at Proxy.requestWrapper.&lt;computed&gt; (/Users/daniellovazzano/Documents/Projects/pet-api-firebase/backend/tests/e2e/helpers/request.js:69:19)
    at Object.&lt;anonymous&gt; (/Users/daniellovazzano/Documents/Projects/pet-api-firebase/backend/tests/e2e/auth/auth.e2e.js:121:32)</failure>
    </testcase>
    <testcase classname="E2E: Auth" name="should list users as admin" time="0.016">
      <failure>AggregateError: 
    at Function.Object.&lt;anonymous&gt;.AxiosError.from (/Users/daniellovazzano/Documents/Projects/pet-api-firebase/backend/node_modules/axios/lib/core/AxiosError.js:92:14)
    at RedirectableRequest.handleRequestError (/Users/daniellovazzano/Documents/Projects/pet-api-firebase/backend/node_modules/axios/lib/adapters/http.js:620:25)
    at RedirectableRequest.emit (node:events:507:28)
    at ClientRequest.eventHandlers.&lt;computed&gt; (/Users/daniellovazzano/Documents/Projects/pet-api-firebase/backend/node_modules/follow-redirects/index.js:49:24)
    at ClientRequest.emit (node:events:507:28)
    at emitErrorEvent (node:_http_client:104:11)
    at Socket.socketErrorListener (node:_http_client:518:5)
    at Socket.emit (node:events:507:28)
    at emitErrorNT (node:internal/streams/destroy:170:8)
    at emitErrorCloseNT (node:internal/streams/destroy:129:3)
    at processTicksAndRejections (node:internal/process/task_queues:90:21)
    at Axios.request (/Users/daniellovazzano/Documents/Projects/pet-api-firebase/backend/node_modules/axios/lib/core/Axios.js:45:41)
    at processTicksAndRejections (node:internal/process/task_queues:105:5)
    at Proxy.requestWrapper.&lt;computed&gt; (/Users/daniellovazzano/Documents/Projects/pet-api-firebase/backend/tests/e2e/helpers/request.js:69:19)
    at Object.&lt;anonymous&gt; (/Users/daniellovazzano/Documents/Projects/pet-api-firebase/backend/tests/e2e/auth/auth.e2e.js:132:22)</failure>
    </testcase>
  </testsuite>
</testsuites>